[{"market":"0xd23bf61367002265932ce5ae32052aac970c889da8518a2487b5e8a5f1e0693b","asset_id":"114602688616062054693464639818826590702731982636255124778328943187816056373369","timestamp":"1788786290337","hash":"6308f06a3a9413b2d1e9576a7e18780daf04ff90","bids":[{"price":"0.01","size":"26.68"},{"price":"0.02","size":"2000"},{"price":"0.03","size":"44.99"},{"price":"0.05","size":"118"},{"price":"0.06","size":"110"},{"price":"0.07","size":"8.57"},{"price":"0.13","size":"50"},{"price":"0.33","size":"1000"},{"price":"0.35","size":"1400"},{"price":"0.36","size":"2145"},{"price":"0.48","size":"500"},{"price":"0.49","size":"125"},{"price":"0.5","size":"300"},{"price":"0.51","size":"7"},{"price":"0.53","size":"5555"},{"price":"0.54","size":"3222"},{"price":"0.55","size":"20927"},{"price":"0.56","size":"4322"},{"price":"0.57","size":"3137"},{"price":"0.58","size":"533"},{"price":"0.59","size":"2045"},{"price":"0.6","size":"2732.32"},{"price":"0.61","size":"5295.12"},{"price":"0.62","size":"35187.53"}],"asks":[{"price":"0.99","size":"1032.63"},{"price":"0.98","size":"2000"},{"price":"0.97","size":"11.12"},{"price":"0.95","size":"300"},{"price":"0.92","size":"3272"},{"price":"0.91","size":"6.66"},{"price":"0.9","size":"110"},{"price":"0.87","size":"50"},{"price":"0.84","size":"500"},{"price":"0.82","size":"77.77"},{"price":"0.79","size":"7.93"},{"price":"0.78","size":"45.45"},{"price":"0.77","size":"300"},{"price":"0.75","size":"300"},{"price":"0.74","size":"17822.07"},{"price":"0.73","size":"772"},{"price":"0.72","size":"3644"},{"price":"0.71","size":"1000"},{"price":"0.7","size":"3929"},{"price":"0.69","size":"9584.93"},{"price":"0.68","size":"13117"},{"price":"0.67","size":"30881"},{"price":"0.66","size":"27665.9"},{"price":"0.65","size":"29150.49"},{"price":"0.64","size":"84811.13"},{"price":"0.63","size":"298.28"}],"tick_size":"0.01","event_type":"book","last_trade_price":"0.620"},{"market":"0xd23bf61367002265932ce5ae32052aac970c889da8518a2487b5e8a5f1e0693b","asset_id":"112222077780534073126353733665449794547376835979729917699348268168151417239731","timestamp":"1788786290337","hash":"e52385968d2029b0050839335af65a31f2992cb8","bids":[{"price":"0.01","size":"1032.63"},{"price":"0.02","size":"2000"},{"price":"0.03","size":"11.12"},{"price":"0.05","size":"300"},{"price":"0.08","size":"3272"},{"price":"0.09","size":"6.66"},{"price":"0.1","size":"110"},{"price":"0.13","size":"50"},{"price":"0.16","size":"500"},{"price":"0.18","size":"77.77"},{"price":"0.21","size":"7.93"},{"price":"0.22","size":"45.45"},{"price":"0.23","size":"300"},{"price":"0.25","size":"300"},{"price":"0.26","size":"17822.07"},{"price":"0.27","size":"772"},{"price":"0.28","size":"3644"},{"price":"0.29","size":"1000"},{"price":"0.3","size":"3929"},{"price":"0.31","size":"9584.93"},{"price":"0.32","size":"13117"},{"price":"0.33","size":"30881"},{"price":"0.34","size":"27665.9"},{"price":"0.35","size":"29150.49"},{"price":"0.36","size":"84811.13"},{"price":"0.37","size":"298.28"}],"asks":[{"price":"0.99","size":"26.68"},{"price":"0.98","size":"2000"},{"price":"0.97","size":"44.99"},{"price":"0.95","size":"118"},{"price":"0.94","size":"110"},{"price":"0.93","size":"8.57"},{"price":"0.87","size":"50"},{"price":"0.67","size":"1000"},{"price":"0.65","size":"1400"},{"price":"0.64","size":"2145"},{"price":"0.52","size":"500"},{"price":"0.51","size":"125"},{"price":"0.5","size":"300"},{"price":"0.49","size":"7"},{"price":"0.47","size":"5555"},{"price":"0.46","size":"3222"},{"price":"0.45","size":"20927"},{"price":"0.44","size":"4322"},{"price":"0.43","size":"3137"},{"price":"0.42","size":"533"},{"price":"0.41","size":"2045"},{"price":"0.4","size":"2732.32"},{"price":"0.39","size":"5295.12"},{"price":"0.38","size":"35187.53"}],"tick_size":"0.01","event_type":"book","last_trade_price":"0.620"}]

{"market":"0xd23bf61367002265932ce5ae32052aac970c889da8518a2487b5e8a5f1e0693b","price_changes":[{"asset_id":"112222077780534073126353733665449794547376835979729917699348268168151417239731","price":"0.09","size":"0","side":"BUY","hash":"8f586c609394aa59b47792c3ade0ec455d30489c","best_bid":"0.37","best_ask":"0.38"},{"asset_id":"114602688616062054693464639818826590702731982636255124778328943187816056373369","price":"0.91","size":"0","side":"SELL","hash":"992ee456f27c0e17ee69beb9ca1f4841360f5eb9","best_bid":"0.62","best_ask":"0.63"}],"timestamp":"1788786330404","event_type":"price_change"}
{"market":"0xd23bf61367002265932ce5ae32052aac970c889da8518a2487b5e8a5f1e0693b","price_changes":[{"asset_id":"114602688616062054693464639818826590702731982636255124778328943187816056373369","price":"0.01","size":"33.04","side":"BUY","hash":"71cdb1813b9564ced291d1943added4960d4d80c","best_bid":"0.62","best_ask":"0.63"},{"asset_id":"112222077780534073126353733665449794547376835979729917699348268168151417239731","price":"0.99","size":"33.04","side":"SELL","hash":"fb81237d63d7067aa57455f36638f52d653c751b","best_bid":"0.37","best_ask":"0.38"}],"timestamp":"1788786330608","event_type":"price_change"}
{"market":"0xd23bf61367002265932ce5ae32052aac970c889da8518a2487b5e8a5f1e0693b","price_changes":[{"asset_id":"112222077780534073126353733665449794547376835979729917699348268168151417239731","price":"0.11","size":"5.45","side":"BUY","hash":"35deb7bb8f83e6238559d5ce4035d4bf42029558","best_bid":"0.37","best_ask":"0.38"},{"asset_id":"114602688616062054693464639818826590702731982636255124778328943187816056373369","price":"0.89","size":"5.45","side":"SELL","hash":"475237d123be151ec65d2d0541bc131f8abbed80","best_bid":"0.62","best_ask":"0.63"}],"timestamp":"1788786331429","event_type":"price_change"}
{"market":"0xd23bf61367002265932ce5ae32052aac970c889da8518a2487b5e8a5f1e0693b","price_changes":[{"asset_id":"112222077780534073126353733665449794547376835979729917699348268168151417239731","price":"0.1","size":"100","side":"BUY","hash":"827e0c71652f0a4da16b023447a07e4c80eb50cc","best_bid":"0.37","best_ask":"0.38"},{"asset_id":"114602688616062054693464639818826590702731982636255124778328943187816056373369","price":"0.9","size":"100","side":"SELL","hash":"e519360124f1f651f976e6d2ed57891da9e33c20","best_bid":"0.62","best_ask":"0.63"}],"timestamp":"1788786331489","event_type":"price_change"}
{"market":"0xd23bf61367002265932ce5ae32052aac970c889da8518a2487b5e8a5f1e0693b","price_changes":[{"asset_id":"112222077780534073126353733665449794547376835979729917699348268168151417239731","price":"0.1","size":"90","side":"BUY","hash":"bcbb9a6366d069de45407903cf7a616987adefb4","best_bid":"0.37","best_ask":"0.38"},{"asset_id":"114602688616062054693464639818826590702731982636255124778328943187816056373369","price":"0.9","size":"90","side":"SELL","hash":"5e3999822cf1595bf7ca1346b8c0bbfbea41661d","best_bid":"0.62","best_ask":"0.63"}],"timestamp":"1788786331494","event_type":"price_change"}
{"market":"0xd23bf61367002265932ce5ae32052aac970c889da8518a2487b5e8a5f1e0693b","price_changes":[{"asset_id":"112222077780534073126353733665449794547376835979729917699348268168151417239731","price":"0.1","size":"80","side":"BUY","hash":"a3e370da6dccaad656dcde339dea06ba89adbc8b","best_bid":"0.37","best_ask":"0.38"},{"asset_id":"114602688616062054693464639818826590702731982636255124778328943187816056373369","price":"0.9","size":"80","side":"SELL","hash":"705e649fc220bf86a4c21749a664204e6f78a1ec","best_bid":"0.62","best_ask":"0.63"}],"timestamp":"1788786331496","event_type":"price_change"}
{"market":"0xd23bf61367002265932ce5ae32052aac970c889da8518a2487b5e8a5f1e0693b","price_changes":[{"asset_id":"112222077780534073126353733665449794547376835979729917699348268168151417239731","price":"0.1","size":"70","side":"BUY","hash":"bc5bef7da1a88ef521cc2107a20a01736c9c190a","best_bid":"0.37","best_ask":"0.38"},{"asset_id":"114602688616062054693464639818826590702731982636255124778328943187816056373369","price":"0.9","size":"70","side":"SELL","hash":"b4b0cdacff138bd26efe6fc65881402221014133","best_bid":"0.62","best_ask":"0.63"}],"timestamp":"1788786331504","event_type":"price_change"}
{"market":"0xd23bf61367002265932ce5ae32052aac970c889da8518a2487b5e8a5f1e0693b","price_changes":[{"asset_id":"112222077780534073126353733665449794547376835979729917699348268168151417239731","price":"0.1","size":"60","side":"BUY","hash":"f522cc2fc7f71401e2d7caa0f2ae486128a84056","best_bid":"0.37","best_ask":"0.38"},{"asset_id":"114602688616062054693464639818826590702731982636255124778328943187816056373369","price":"0.9","size":"60","side":"SELL","hash":"ff7a387f723885c6c780dc0ad38a58a4a087163b","best_bid":"0.62","best_ask":"0.63"}],"timestamp":"1788786331522","event_type":"price_change"}
{"market":"0xd23bf61367002265932ce5ae32052aac970c889da8518a2487b5e8a5f1e0693b","price_changes":[{"asset_id":"112222077780534073126353733665449794547376835979729917699348268168151417239731","price":"0.1","size":"50","side":"BUY","hash":"0fce27aef221ad479cd61a5fd83d68f11194b607","best_bid":"0.37","best_ask":"0.38"},{"asset_id":"114602688616062054693464639818826590702731982636255124778328943187816056373369","price":"0.9","size":"50","side":"SELL","hash":"33fa94c2184ad0a5893c8fe8cdb5a52820ec09d6","best_bid":"0.62","best_ask":"0.63"}],"timestamp":"1788786331526","event_type":"price_change"}
{"market":"0xd23bf61367002265932ce5ae32052aac970c889da8518a2487b5e8a5f1e0693b","price_changes":[{"asset_id":"112222077780534073126353733665449794547376835979729917699348268168151417239731","price":"0.1","size":"40","side":"BUY","hash":"11fcc5271c79bc297ef2ee9174fda0f67f584f9a","best_bid":"0.37","best_ask":"0.38"},{"asset_id":"114602688616062054693464639818826590702731982636255124778328943187816056373369","price":"0.9","size":"40","side":"SELL","hash":"65e70868c7ad6d78852b95ffec7d60074d561510","best_bid":"0.62","best_ask":"0.63"}],"timestamp":"1788786331530","event_type":"price_change"}
{"market":"0xd23bf61367002265932ce5ae32052aac970c889da8518a2487b5e8a5f1e0693b","price_changes":[{"asset_id":"112222077780534073126353733665449794547376835979729917699348268168151417239731","price":"0.1","size":"30","side":"BUY","hash":"3aa8edb1d072664d378b293e8eb0aaaf4f160885","best_bid":"0.37","best_ask":"0.38"},{"asset_id":"114602688616062054693464639818826590702731982636255124778328943187816056373369","price":"0.9","size":"30","side":"SELL","hash":"e12b4940fbe0ca33be3fb1815b9efc3a8e6bdf69","best_bid":"0.62","best_ask":"0.63"}],"timestamp":"1788786331539","event_type":"price_change"}
{"market":"0xd23bf61367002265932ce5ae32052aac970c889da8518a2487b5e8a5f1e0693b","price_changes":[{"asset_id":"112222077780534073126353733665449794547376835979729917699348268168151417239731","price":"0.1","size":"20","side":"BUY","hash":"aa42ea8b00e5ea99fcff42e311d246432dfd1ef7","best_bid":"0.37","best_ask":"0.38"},{"asset_id":"114602688616062054693464639818826590702731982636255124778328943187816056373369","price":"0.9","size":"20","side":"SELL","hash":"ccd9051f0b74ac85509bd46b05dd4ad36c50c3da","best_bid":"0.62","best_ask":"0.63"}],"timestamp":"1788786331560","event_type":"price_change"}
{"market":"0xd23bf61367002265932ce5ae32052aac970c889da8518a2487b5e8a5f1e0693b","price_changes":[{"asset_id":"112222077780534073126353733665449794547376835979729917699348268168151417239731","price":"0.1","size":"10","side":"BUY","hash":"fb5f2a19d40381e82558b79d93e806628cfb1f33","best_bid":"0.37","best_ask":"0.38"},{"asset_id":"114602688616062054693464639818826590702731982636255124778328943187816056373369","price":"0.9","size":"10","side":"SELL","hash":"efa15b4c35c48e4f92203e775328700a0d8e9e96","best_bid":"0.62","best_ask":"0.63"}],"timestamp":"1788786331572","event_type":"price_change"}
{"market":"0xd23bf61367002265932ce5ae32052aac970c889da8518a2487b5e8a5f1e0693b","price_changes":[{"asset_id":"112222077780534073126353733665449794547376835979729917699348268168151417239731","price":"0.1","size":"0","side":"BUY","hash":"2f073484f5cb5e08dc4e09cb5dabb96d1424314e","best_bid":"0.37","best_ask":"0.38"},{"asset_id":"114602688616062054693464639818826590702731982636255124778328943187816056373369","price":"0.9","size":"0","side":"SELL","hash":"e6536b31b9087bd005a09feeb8ce93397667f46d","best_bid":"0.62","best_ask":"0.63"}],"timestamp":"1788786331577","event_type":"price_change"}
{"market":"0xd23bf61367002265932ce5ae32052aac970c889da8518a2487b5e8a5f1e0693b","price_changes":[{"asset_id":"112222077780534073126353733665449794547376835979729917699348268168151417239731","price":"0.11","size":"15.45","side":"BUY","hash":"08a5eaf4a4ccd8df53a7e01ee38faf3e372f45bc","best_bid":"0.37","best_ask":"0.38"},{"asset_id":"114602688616062054693464639818826590702731982636255124778328943187816056373369","price":"0.89","size":"15.45","side":"SELL","hash":"7cf6261c5d53519c867e7826d371b4e989712114","best_bid":"0.62","best_ask":"0.63"}],"timestamp":"1788786331596","event_type":"price_change"}
{"market":"0xd23bf61367002265932ce5ae32052aac970c889da8518a2487b5e8a5f1e0693b","price_changes":[{"asset_id":"112222077780534073126353733665449794547376835979729917699348268168151417239731","price":"0.11","size":"25.45","side":"BUY","hash":"4a1a25ea052b0e7e65cb20181f7d7c88cbd5012d","best_bid":"0.37","best_ask":"0.38"},{"asset_id":"114602688616062054693464639818826590702731982636255124778328943187816056373369","price":"0.89","size":"25.45","side":"SELL","hash":"b203834e5037f1c0cb579edd4a5490191d71fabc","best_bid":"0.62","best_ask":"0.63"}],"timestamp":"1788786331598","event_type":"price_change"}
{"market":"0xd23bf61367002265932ce5ae32052aac970c889da8518a2487b5e8a5f1e0693b","price_changes":[{"asset_id":"112222077780534073126353733665449794547376835979729917699348268168151417239731","price":"0.11","size":"35.45","side":"BUY","hash":"c511fb5f28400c3da19eb554d06d5891809d517d","best_bid":"0.37","best_ask":"0.38"},{"asset_id":"114602688616062054693464639818826590702731982636255124778328943187816056373369","price":"0.89","size":"35.45","side":"SELL","hash":"d91f9f6e9b2ea4956eea9dc9ba4f3c0b3d74a375","best_bid":"0.62","best_ask":"0.63"}],"timestamp":"1788786331602","event_type":"price_change"}
{"market":"0xd23bf61367002265932ce5ae32052aac970c889da8518a2487b5e8a5f1e0693b","price_changes":[{"asset_id":"112222077780534073126353733665449794547376835979729917699348268168151417239731","price":"0.11","size":"45.45","side":"BUY","hash":"0958fe2fad5f08e186d55c2f0fe4656669d560ee","best_bid":"0.37","best_ask":"0.38"},{"asset_id":"114602688616062054693464639818826590702731982636255124778328943187816056373369","price":"0.89","size":"45.45","side":"SELL","hash":"49e032f582a62af0088d76930e8064352f09a633","best_bid":"0.62","best_ask":"0.63"}],"timestamp":"1788786331608","event_type":"price_change"}
{"market":"0xd23bf61367002265932ce5ae32052aac970c889da8518a2487b5e8a5f1e0693b","price_changes":[{"asset_id":"112222077780534073126353733665449794547376835979729917699348268168151417239731","price":"0.12","size":"10","side":"BUY","hash":"6166c575efdec8ce6b826796a02e0a4a54653aaa","best_bid":"0.37","best_ask":"0.38"},{"asset_id":"114602688616062054693464639818826590702731982636255124778328943187816056373369","price":"0.88","size":"10","side":"SELL","hash":"32c0023ee4a905204a694f3bd0d72cf74f237572","best_bid":"0.62","best_ask":"0.63"}],"timestamp":"1788786331628","event_type":"price_change"}
{"market":"0xd23bf61367002265932ce5ae32052aac970c889da8518a2487b5e8a5f1e0693b","price_changes":[{"asset_id":"112222077780534073126353733665449794547376835979729917699348268168151417239731","price":"0.11","size":"55.45","side":"BUY","hash":"88b90960551d8fc72d6051aed1800a96ff3ac53b","best_bid":"0.37","best_ask":"0.38"},{"asset_id":"114602688616062054693464639818826590702731982636255124778328943187816056373369","price":"0.89","size":"55.45","side":"SELL","hash":"97971c6cba734992ebba9efc13341e611adaddfa","best_bid":"0.62","best_ask":"0.63"}],"timestamp":"1788786331629","event_type":"price_change"}
{"market":"0xd23bf61367002265932ce5ae32052aac970c889da8518a2487b5e8a5f1e0693b","price_changes":[{"asset_id":"112222077780534073126353733665449794547376835979729917699348268168151417239731","price":"0.11","size":"65.45","side":"BUY","hash":"2cb8986821f611aea5c8c265a5f053bc8c324174","best_bid":"0.37","best_ask":"0.38"},{"asset_id":"114602688616062054693464639818826590702731982636255124778328943187816056373369","price":"0.89","size":"65.45","side":"SELL","hash":"e81b7ba56dd4a878f458c68e4aba80cbe08c9d75","best_bid":"0.62","best_ask":"0.63"}],"timestamp":"1788786331632","event_type":"price_change"}
{"market":"0xd23bf61367002265932ce5ae32052aac970c889da8518a2487b5e8a5f1e0693b","price_changes":[{"asset_id":"112222077780534073126353733665449794547376835979729917699348268168151417239731","price":"0.11","size":"75.45","side":"BUY","hash":"6bd172cb87263a3c2463705036881e96b3554fd7","best_bid":"0.37","best_ask":"0.38"},{"asset_id":"114602688616062054693464639818826590702731982636255124778328943187816056373369","price":"0.89","size":"75.45","side":"SELL","hash":"3e877641adc693c6607b22477bcb6e004c32fca5","best_bid":"0.62","best_ask":"0.63"}],"timestamp":"1788786331641","event_type":"price_change"}
{"market":"0xd23bf61367002265932ce5ae32052aac970c889da8518a2487b5e8a5f1e0693b","price_changes":[{"asset_id":"112222077780534073126353733665449794547376835979729917699348268168151417239731","price":"0.11","size":"85.45","side":"BUY","hash":"4e0ce263162f4def60fafe970358aa7030e76ad0","best_bid":"0.37","best_ask":"0.38"},{"asset_id":"114602688616062054693464639818826590702731982636255124778328943187816056373369","price":"0.89","size":"85.45","side":"SELL","hash":"e0a121596afa5f99ea43dd7411069be99afab4c0","best_bid":"0.62","best_ask":"0.63"}],"timestamp":"1788786331644","event_type":"price_change"}
{"market":"0xd23bf61367002265932ce5ae32052aac970c889da8518a2487b5e8a5f1e0693b","price_changes":[{"asset_id":"112222077780534073126353733665449794547376835979729917699348268168151417239731","price":"0.12","size":"20","side":"BUY","hash":"58ab3e601f67187c592bd2064e34b65ba3a02c6c","best_bid":"0.37","best_ask":"0.38"},{"asset_id":"114602688616062054693464639818826590702731982636255124778328943187816056373369","price":"0.88","size":"20","side":"SELL","hash":"a122d473779e7fa6c7e4ab2fea12c222bde76421","best_bid":"0.62","best_ask":"0.63"}],"timestamp":"1788786331670","event_type":"price_change"}
{"market":"0xd23bf61367002265932ce5ae32052aac970c889da8518a2487b5e8a5f1e0693b","price_changes":[{"asset_id":"112222077780534073126353733665449794547376835979729917699348268168151417239731","price":"0.12","size":"30","side":"BUY","hash":"ddec02c6bd0566a94f3775f68f8e462c9c7bfebb","best_bid":"0.37","best_ask":"0.38"},{"asset_id":"114602688616062054693464639818826590702731982636255124778328943187816056373369","price":"0.88","size":"30","side":"SELL","hash":"f71de6f9c3124d101f36c29eff79784612f58bfd","best_bid":"0.62","best_ask":"0.63"}],"timestamp":"1788786331681","event_type":"price_change"}
{"market":"0xd23bf61367002265932ce5ae32052aac970c889da8518a2487b5e8a5f1e0693b","price_changes":[{"asset_id":"112222077780534073126353733665449794547376835979729917699348268168151417239731","price":"0.11","size":"75.45","side":"BUY","hash":"258dba9571f8ecc24046a6b84fbd11353d256fae","best_bid":"0.37","best_ask":"0.38"},{"asset_id":"114602688616062054693464639818826590702731982636255124778328943187816056373369","price":"0.89","size":"75.45","side":"SELL","hash":"515d368614fecbd87458804979ddc403bffb0516","best_bid":"0.62","best_ask":"0.63"}],"timestamp":"1788786331690","event_type":"price_change"}
{"market":"0xd23bf61367002265932ce5ae32052aac970c889da8518a2487b5e8a5f1e0693b","price_changes":[{"asset_id":"112222077780534073126353733665449794547376835979729917699348268168151417239731","price":"0.11","size":"65.45","side":"BUY","hash":"50c56112c5aca9ed6bf9d304ffa38358be56172f","best_bid":"0.37","best_ask":"0.38"},{"asset_id":"114602688616062054693464639818826590702731982636255124778328943187816056373369","price":"0.89","size":"65.45","side":"SELL","hash":"6dde2bd64c804a2da81eb5f86f0085222d7a516b","best_bid":"0.62","best_ask":"0.63"}],"timestamp":"1788786331693","event_type":"price_change"}
{"market":"0xd23bf61367002265932ce5ae32052aac970c889da8518a2487b5e8a5f1e0693b","price_changes":[{"asset_id":"112222077780534073126353733665449794547376835979729917699348268168151417239731","price":"0.11","size":"55.45","side":"BUY","hash":"c6a5218e86b26735b028ea5ab83394d8488586b9","best_bid":"0.37","best_ask":"0.38"},{"asset_id":"114602688616062054693464639818826590702731982636255124778328943187816056373369","price":"0.89","size":"55.45","side":"SELL","hash":"b7d669fca8ce2bb36fa87ae8a9941e60b37682eb","best_bid":"0.62","best_ask":"0.63"}],"timestamp":"1788786331695","event_type":"price_change"}
{"market":"0xd23bf61367002265932ce5ae32052aac970c889da8518a2487b5e8a5f1e0693b","price_changes":[{"asset_id":"112222077780534073126353733665449794547376835979729917699348268168151417239731","price":"0.11","size":"45.45","side":"BUY","hash":"d9c0cef9746ed569c21280b345c566f37bbbe571","best_bid":"0.37","best_ask":"0.38"},{"asset_id":"114602688616062054693464639818826590702731982636255124778328943187816056373369","price":"0.89","size":"45.45","side":"SELL","hash":"f36b0299f9710a05997b6b7b8d9eceb455ff760a","best_bid":"0.62","best_ask":"0.63"}],"timestamp":"1788786331697","event_type":"price_change"}
{"market":"0xd23bf61367002265932ce5ae32052aac970c889da8518a2487b5e8a5f1e0693b","price_changes":[{"asset_id":"112222077780534073126353733665449794547376835979729917699348268168151417239731","price":"0.11","size":"35.45","side":"BUY","hash":"b76eb5b1052592f562db620250be4c5d535fab2b","best_bid":"0.37","best_ask":"0.38"},{"asset_id":"114602688616062054693464639818826590702731982636255124778328943187816056373369","price":"0.89","size":"35.45","side":"SELL","hash":"23d13529bb4f779f6de55a69d4a8d34024ed610b","best_bid":"0.62","best_ask":"0.63"}],"timestamp":"1788786331726","event_type":"price_change"}
{"market":"0xd23bf61367002265932ce5ae32052aac970c889da8518a2487b5e8a5f1e0693b","price_changes":[{"asset_id":"112222077780534073126353733665449794547376835979729917699348268168151417239731","price":"0.11","size":"25.45","side":"BUY","hash":"6457d0b0c06793c48c5e8da2becdf676083c978b","best_bid":"0.37","best_ask":"0.38"},{"asset_id":"114602688616062054693464639818826590702731982636255124778328943187816056373369","price":"0.89","size":"25.45","side":"SELL","hash":"d0e11a36d771c47335858ad211135b5d899c6aa4","best_bid":"0.62","best_ask":"0.63"}],"timestamp":"1788786331729","event_type":"price_change"}
{"market":"0xd23bf61367002265932ce5ae32052aac970c889da8518a2487b5e8a5f1e0693b","price_changes":[{"asset_id":"112222077780534073126353733665449794547376835979729917699348268168151417239731","price":"0.11","size":"15.45","side":"BUY","hash":"5ec7958010695d528dc0c750831eb722d12d1bc6","best_bid":"0.37","best_ask":"0.38"},{"asset_id":"114602688616062054693464639818826590702731982636255124778328943187816056373369","price":"0.89","size":"15.45","side":"SELL","hash":"f9b617703a7ce84084dc13ea2cca25e05fe19843","best_bid":"0.62","best_ask":"0.63"}],"timestamp":"1788786331735","event_type":"price_change"}
{"market":"0xd23bf61367002265932ce5ae32052aac970c889da8518a2487b5e8a5f1e0693b","price_changes":[{"asset_id":"112222077780534073126353733665449794547376835979729917699348268168151417239731","price":"0.11","size":"5.45","side":"BUY","hash":"63ef33df885f61262c9f2bec9d1853727fd40e2a","best_bid":"0.37","best_ask":"0.38"},{"asset_id":"114602688616062054693464639818826590702731982636255124778328943187816056373369","price":"0.89","size":"5.45","side":"SELL","hash":"5ab1babf6e980d543947ab56a4867f3b1a2357e3","best_bid":"0.62","best_ask":"0.63"}],"timestamp":"1788786331738","event_type":"price_change"}
{"market":"0xd23bf61367002265932ce5ae32052aac970c889da8518a2487b5e8a5f1e0693b","price_changes":[{"asset_id":"112222077780534073126353733665449794547376835979729917699348268168151417239731","price":"0.12","size":"40","side":"BUY","hash":"9d56046e8e8663a22889dedaa789699527e36add","best_bid":"0.37","best_ask":"0.38"},{"asset_id":"114602688616062054693464639818826590702731982636255124778328943187816056373369","price":"0.88","size":"40","side":"SELL","hash":"0c99922e00bbf3bb62d21270105b44e8bed43d73","best_bid":"0.62","best_ask":"0.63"}],"timestamp":"1788786331794","event_type":"price_change"}
{"market":"0xd23bf61367002265932ce5ae32052aac970c889da8518a2487b5e8a5f1e0693b","price_changes":[{"asset_id":"112222077780534073126353733665449794547376835979729917699348268168151417239731","price":"0.12","size":"50","side":"BUY","hash":"f3dd42a89806ceb57663cf22947f2eb3358af992","best_bid":"0.37","best_ask":"0.38"},{"asset_id":"114602688616062054693464639818826590702731982636255124778328943187816056373369","price":"0.88","size":"50","side":"SELL","hash":"7100c1a13641db8c6298882a9cfdff017951023d","best_bid":"0.62","best_ask":"0.63"}],"timestamp":"1788786331798","event_type":"price_change"}
{"market":"0xd23bf61367002265932ce5ae32052aac970c889da8518a2487b5e8a5f1e0693b","price_changes":[{"asset_id":"112222077780534073126353733665449794547376835979729917699348268168151417239731","price":"0.12","size":"60","side":"BUY","hash":"5754082c544b6c328e40b68f14d517d7babf88df","best_bid":"0.37","best_ask":"0.38"},{"asset_id":"114602688616062054693464639818826590702731982636255124778328943187816056373369","price":"0.88","size":"60","side":"SELL","hash":"85b8a9d8990c90d4f38505858c256596a5c4e6fd","best_bid":"0.62","best_ask":"0.63"}],"timestamp":"1788786331800","event_type":"price_change"}
{"market":"0xd23bf61367002265932ce5ae32052aac970c889da8518a2487b5e8a5f1e0693b","price_changes":[{"asset_id":"112222077780534073126353733665449794547376835979729917699348268168151417239731","price":"0.12","size":"70","side":"BUY","hash":"c116d55796ecda90189c44c37a59771c4129ce16","best_bid":"0.37","best_ask":"0.38"},{"asset_id":"114602688616062054693464639818826590702731982636255124778328943187816056373369","price":"0.88","size":"70","side":"SELL","hash":"e4c92b5c49fd0e3c227d608a60c639e530ef558d","best_bid":"0.62","best_ask":"0.63"}],"timestamp":"1788786331807","event_type":"price_change"}
{"market":"0xd23bf61367002265932ce5ae32052aac970c889da8518a2487b5e8a5f1e0693b","price_changes":[{"asset_id":"112222077780534073126353733665449794547376835979729917699348268168151417239731","price":"0.12","size":"80","side":"BUY","hash":"76d252073f0b2e0510ba9cb8be31df7933f1ddb7","best_bid":"0.37","best_ask":"0.38"},{"asset_id":"114602688616062054693464639818826590702731982636255124778328943187816056373369","price":"0.88","size":"80","side":"SELL","hash":"bce8fefb15d374abe774d453c17d9f6b34e42c0b","best_bid":"0.62","best_ask":"0.63"}],"timestamp":"1788786331828","event_type":"price_change"}
{"market":"0xd23bf61367002265932ce5ae32052aac970c889da8518a2487b5e8a5f1e0693b","price_changes":[{"asset_id":"112222077780534073126353733665449794547376835979729917699348268168151417239731","price":"0.12","size":"90","side":"BUY","hash":"340723da05df98b2202d7cadb88620fc00be17e0","best_bid":"0.37","best_ask":"0.38"},{"asset_id":"114602688616062054693464639818826590702731982636255124778328943187816056373369","price":"0.88","size":"90","side":"SELL","hash":"06f44cac3b2d186d81f14ebcafd8bf1491804a4d","best_bid":"0.62","best_ask":"0.63"}],"timestamp":"1788786331832","event_type":"price_change"}
{"market":"0xd23bf61367002265932ce5ae32052aac970c889da8518a2487b5e8a5f1e0693b","price_changes":[{"asset_id":"112222077780534073126353733665449794547376835979729917699348268168151417239731","price":"0.12","size":"100","side":"BUY","hash":"d82f231b4bee7bb9839890629d60af7f0da46a73","best_bid":"0.37","best_ask":"0.38"},{"asset_id":"114602688616062054693464639818826590702731982636255124778328943187816056373369","price":"0.88","size":"100","side":"SELL","hash":"956889be2d7218034a9609fba04060f455478cf2","best_bid":"0.62","best_ask":"0.63"}],"timestamp":"1788786331842","event_type":"price_change"}
{"market":"0xd23bf61367002265932ce5ae32052aac970c889da8518a2487b5e8a5f1e0693b","price_changes":[{"asset_id":"112222077780534073126353733665449794547376835979729917699348268168151417239731","price":"0.12","size":"110","side":"BUY","hash":"044b81b5581dd328ea3b2e5ac3e0b3e1a8d9deaa","best_bid":"0.37","best_ask":"0.38"},{"asset_id":"114602688616062054693464639818826590702731982636255124778328943187816056373369","price":"0.88","size":"110","side":"SELL","hash":"d785f2d86f3306a8ddb04c6e480f9d6ecb915996","best_bid":"0.62","best_ask":"0.63"}],"timestamp":"1788786331843","event_type":"price_change"}
{"market":"0xd23bf61367002265932ce5ae32052aac970c889da8518a2487b5e8a5f1e0693b","price_changes":[{"asset_id":"114602688616062054693464639818826590702731982636255124778328943187816056373369","price":"0.69","size":"9591.93","side":"SELL","hash":"cac325bbf61fc963298e2f0f93b3ed608def00b3","best_bid":"0.62","best_ask":"0.63"},{"asset_id":"112222077780534073126353733665449794547376835979729917699348268168151417239731","price":"0.31","size":"9591.93","side":"BUY","hash":"844f598f02f49223e4d6849d0194914e636fc7d0","best_bid":"0.37","best_ask":"0.38"}],"timestamp":"1788786337920","event_type":"price_change"}
{"market":"0xd23bf61367002265932ce5ae32052aac970c889da8518a2487b5e8a5f1e0693b","price_changes":[{"asset_id":"114602688616062054693464639818826590702731982636255124778328943187816056373369","price":"0.68","size":"13138","side":"SELL","hash":"917bae6ee73f6632d65f933d2bff689dd368bed8","best_bid":"0.62","best_ask":"0.63"},{"asset_id":"112222077780534073126353733665449794547376835979729917699348268168151417239731","price":"0.32","size":"13138","side":"BUY","hash":"20d8e3f48ab81a370941ef3c60a55f286cf03de5","best_bid":"0.37","best_ask":"0.38"}],"timestamp":"1788786337921","event_type":"price_change"}
{"market":"0xd23bf61367002265932ce5ae32052aac970c889da8518a2487b5e8a5f1e0693b","price_changes":[{"asset_id":"114602688616062054693464639818826590702731982636255124778328943187816056373369","price":"0.62","size":"35182.53","side":"BUY","hash":"24c230f98edf1b8aeaef80d4cf2619865d694006","best_bid":"0.62","best_ask":"0.63"},{"asset_id":"112222077780534073126353733665449794547376835979729917699348268168151417239731","price":"0.38","size":"35182.53","side":"SELL","hash":"1fbf0987d59276d99ad5e209afd6196923cf9479","best_bid":"0.37","best_ask":"0.38"}],"timestamp":"1788786340858","event_type":"price_change"}
{"market":"0xd23bf61367002265932ce5ae32052aac970c889da8518a2487b5e8a5f1e0693b","price_changes":[{"asset_id":"112222077780534073126353733665449794547376835979729917699348268168151417239731","price":"0.36","size":"84806.13","side":"BUY","hash":"56d629b8b834fd69fadd905ba116582f245251a1","best_bid":"0.37","best_ask":"0.38"},{"asset_id":"114602688616062054693464639818826590702731982636255124778328943187816056373369","price":"0.64","size":"84806.13","side":"SELL","hash":"248a17b31f25937d3d81f7bda984e87520682cd4","best_bid":"0.62","best_ask":"0.63"}],"timestamp":"1788786345263","event_type":"price_change"}
{"market":"0xd23bf61367002265932ce5ae32052aac970c889da8518a2487b5e8a5f1e0693b","price_changes":[{"asset_id":"114602688616062054693464639818826590702731982636255124778328943187816056373369","price":"0.62","size":"35150.79","side":"BUY","hash":"a56b837b3ac2048fbcf3e04b4cd9709734b037ce","best_bid":"0.62","best_ask":"0.63"},{"asset_id":"112222077780534073126353733665449794547376835979729917699348268168151417239731","price":"0.38","size":"35150.79","side":"SELL","hash":"f2ae1fa12728286d524d00b3b7fb0ee01060c29b","best_bid":"0.37","best_ask":"0.38"}],"timestamp":"1788786353240","event_type":"price_change"}
{"market":"0xd23bf61367002265932ce5ae32052aac970c889da8518a2487b5e8a5f1e0693b","asset_id":"114602688616062054693464639818826590702731982636255124778328943187816056373369","bids":[{"price":"0.01","size":"33.04"},{"price":"0.02","size":"2000"},{"price":"0.03","size":"44.99"},{"price":"0.05","size":"118"},{"price":"0.06","size":"110"},{"price":"0.07","size":"8.57"},{"price":"0.13","size":"50"},{"price":"0.33","size":"1000"},{"price":"0.35","size":"1400"},{"price":"0.36","size":"2145"},{"price":"0.48","size":"500"},{"price":"0.49","size":"125"},{"price":"0.5","size":"300"},{"price":"0.51","size":"7"},{"price":"0.53","size":"5555"},{"price":"0.54","size":"3222"},{"price":"0.55","size":"20927"},{"price":"0.56","size":"4322"},{"price":"0.57","size":"3137"},{"price":"0.58","size":"533"},{"price":"0.59","size":"2045"},{"price":"0.6","size":"2732.32"},{"price":"0.61","size":"5295.12"},{"price":"0.62","size":"35150.79"}],"asks":[{"price":"0.99","size":"1032.63"},{"price":"0.98","size":"2000"},{"price":"0.97","size":"11.12"},{"price":"0.95","size":"300"},{"price":"0.92","size":"3272"},{"price":"0.89","size":"5.45"},{"price":"0.88","size":"110"},{"price":"0.87","size":"50"},{"price":"0.84","size":"500"},{"price":"0.82","size":"77.77"},{"price":"0.79","size":"7.93"},{"price":"0.78","size":"45.45"},{"price":"0.77","size":"300"},{"price":"0.75","size":"300"},{"price":"0.74","size":"17822.07"},{"price":"0.73","size":"772"},{"price":"0.72","size":"3644"},{"price":"0.71","size":"1000"},{"price":"0.7","size":"3929"},{"price":"0.69","size":"9591.93"},{"price":"0.68","size":"13138"},{"price":"0.67","size":"30881"},{"price":"0.66","size":"27665.9"},{"price":"0.65","size":"29150.49"},{"price":"0.64","size":"84806.13"},{"price":"0.63","size":"298.28"}],"hash":"a56b837b3ac2048fbcf3e04b4cd9709734b037ce","timestamp":"1788786353240","event_type":"book"}
{"market":"0xd23bf61367002265932ce5ae32052aac970c889da8518a2487b5e8a5f1e0693b","asset_id":"112222077780534073126353733665449794547376835979729917699348268168151417239731","bids":[{"price":"0.01","size":"1032.63"},{"price":"0.02","size":"2000"},{"price":"0.03","size":"11.12"},{"price":"0.05","size":"300"},{"price":"0.08","size":"3272"},{"price":"0.11","size":"5.45"},{"price":"0.12","size":"110"},{"price":"0.13","size":"50"},{"price":"0.16","size":"500"},{"price":"0.18","size":"77.77"},{"price":"0.21","size":"7.93"},{"price":"0.22","size":"45.45"},{"price":"0.23","size":"300"},{"price":"0.25","size":"300"},{"price":"0.26","size":"17822.07"},{"price":"0.27","size":"772"},{"price":"0.28","size":"3644"},{"price":"0.29","size":"1000"},{"price":"0.3","size":"3929"},{"price":"0.31","size":"9591.93"},{"price":"0.32","size":"13138"},{"price":"0.33","size":"30881"},{"price":"0.34","size":"27665.9"},{"price":"0.35","size":"29150.49"},{"price":"0.36","size":"84806.13"},{"price":"0.37","size":"298.28"}],"asks":[{"price":"0.99","size":"33.04"},{"price":"0.98","size":"2000"},{"price":"0.97","size":"44.99"},{"price":"0.95","size":"118"},{"price":"0.94","size":"110"},{"price":"0.93","size":"8.57"},{"price":"0.87","size":"50"},{"price":"0.67","size":"1000"},{"price":"0.65","size":"1400"},{"price":"0.64","size":"2145"},{"price":"0.52","size":"500"},{"price":"0.51","size":"125"},{"price":"0.5","size":"300"},{"price":"0.49","size":"7"},{"price":"0.47","size":"5555"},{"price":"0.46","size":"3222"},{"price":"0.45","size":"20927"},{"price":"0.44","size":"4322"},{"price":"0.43","size":"3137"},{"price":"0.42","size":"533"},{"price":"0.41","size":"2045"},{"price":"0.4","size":"2732.32"},{"price":"0.39","size":"5295.12"},{"price":"0.38","size":"35150.79"}],"hash":"f2ae1fa12728286d524d00b3b7fb0ee01060c29b","timestamp":"1788786353240","event_type":"book"}
{"market":"0xd23bf61367002265932ce5ae32052aac970c889da8518a2487b5e8a5f1e0693b","asset_id":"114602688616062054693464639818826590702731982636255124778328943187816056373369","price":"0.62","size":"31.74","fee_rate_bps":"0","side":"SELL","timestamp":"1788786353325","event_type":"last_trade_price","transaction_hash":"0x99fca9e17a22a7f836895b84abe0fb82fb892e6ffa2a4f3127cdf5055b3e7687"}
{"market":"0xd23bf61367002265932ce5ae32052aac970c889da8518a2487b5e8a5f1e0693b","price_changes":[{"asset_id":"114602688616062054693464639818826590702731982636255124778328943187816056373369","price":"0.61","size":"5245.12","side":"BUY","hash":"02970ea7c4cad80fc0fae08f4bbc5c14737569ca","best_bid":"0.62","best_ask":"0.63"},{"asset_id":"112222077780534073126353733665449794547376835979729917699348268168151417239731","price":"0.39","size":"5245.12","side":"SELL","hash":"39045a1015c30f191c54a3da2ffb172c86216f48","best_bid":"0.37","best_ask":"0.38"}],"timestamp":"1788786374640","event_type":"price_change"}
{"market":"0xd23bf61367002265932ce5ae32052aac970c889da8518a2487b5e8a5f1e0693b","price_changes":[{"asset_id":"112222077780534073126353733665449794547376835979729917699348268168151417239731","price":"0.34","size":"27615.9","side":"BUY","hash":"39045a1015c30f191c54a3da2ffb172c86216f48","best_bid":"0.37","best_ask":"0.38"},{"asset_id":"114602688616062054693464639818826590702731982636255124778328943187816056373369","price":"0.66","size":"27615.9","side":"SELL","hash":"02970ea7c4cad80fc0fae08f4bbc5c14737569ca","best_bid":"0.62","best_ask":"0.63"}],"timestamp":"1788786374640","event_type":"price_change"}
{"market":"0xd23bf61367002265932ce5ae32052aac970c889da8518a2487b5e8a5f1e0693b","price_changes":[{"asset_id":"114602688616062054693464639818826590702731982636255124778328943187816056373369","price":"0.63","size":"290.72","side":"SELL","hash":"fcb3fd4e51d0e34b0556941a068ebb024ab91290","best_bid":"0.62","best_ask":"0.63"},{"asset_id":"112222077780534073126353733665449794547376835979729917699348268168151417239731","price":"0.37","size":"290.72","side":"BUY","hash":"2940c6d9560658d95dfb1c58a6f7120563058b79","best_bid":"0.37","best_ask":"0.38"}],"timestamp":"1788786377421","event_type":"price_change"}
{"market":"0xd23bf61367002265932ce5ae32052aac970c889da8518a2487b5e8a5f1e0693b","asset_id":"114602688616062054693464639818826590702731982636255124778328943187816056373369","bids":[{"price":"0.01","size":"33.04"},{"price":"0.02","size":"2000"},{"price":"0.03","size":"44.99"},{"price":"0.05","size":"118"},{"price":"0.06","size":"110"},{"price":"0.07","size":"8.57"},{"price":"0.13","size":"50"},{"price":"0.33","size":"1000"},{"price":"0.35","size":"1400"},{"price":"0.36","size":"2145"},{"price":"0.48","size":"500"},{"price":"0.49","size":"125"},{"price":"0.5","size":"300"},{"price":"0.51","size":"7"},{"price":"0.53","size":"5555"},{"price":"0.54","size":"3222"},{"price":"0.55","size":"20927"},{"price":"0.56","size":"4322"},{"price":"0.57","size":"3137"},{"price":"0.58","size":"533"},{"price":"0.59","size":"2045"},{"price":"0.6","size":"2732.32"},{"price":"0.61","size":"5245.12"},{"price":"0.62","size":"35150.79"}],"asks":[{"price":"0.99","size":"1032.63"},{"price":"0.98","size":"2000"},{"price":"0.97","size":"11.12"},{"price":"0.95","size":"300"},{"price":"0.92","size":"3272"},{"price":"0.89","size":"5.45"},{"price":"0.88","size":"110"},{"price":"0.87","size":"50"},{"price":"0.84","size":"500"},{"price":"0.82","size":"77.77"},{"price":"0.79","size":"7.93"},{"price":"0.78","size":"45.45"},{"price":"0.77","size":"300"},{"price":"0.75","size":"300"},{"price":"0.74","size":"17822.07"},{"price":"0.73","size":"772"},{"price":"0.72","size":"3644"},{"price":"0.71","size":"1000"},{"price":"0.7","size":"3929"},{"price":"0.69","size":"9591.93"},{"price":"0.68","size":"13138"},{"price":"0.67","size":"30881"},{"price":"0.66","size":"27615.9"},{"price":"0.65","size":"29150.49"},{"price":"0.64","size":"84806.13"},{"price":"0.63","size":"290.72"}],"hash":"fcb3fd4e51d0e34b0556941a068ebb024ab91290","timestamp":"1788786377421","event_type":"book"}
{"market":"0xd23bf61367002265932ce5ae32052aac970c889da8518a2487b5e8a5f1e0693b","asset_id":"112222077780534073126353733665449794547376835979729917699348268168151417239731","bids":[{"price":"0.01","size":"1032.63"},{"price":"0.02","size":"2000"},{"price":"0.03","size":"11.12"},{"price":"0.05","size":"300"},{"price":"0.08","size":"3272"},{"price":"0.11","size":"5.45"},{"price":"0.12","size":"110"},{"price":"0.13","size":"50"},{"price":"0.16","size":"500"},{"price":"0.18","size":"77.77"},{"price":"0.21","size":"7.93"},{"price":"0.22","size":"45.45"},{"price":"0.23","size":"300"},{"price":"0.25","size":"300"},{"price":"0.26","size":"17822.07"},{"price":"0.27","size":"772"},{"price":"0.28","size":"3644"},{"price":"0.29","size":"1000"},{"price":"0.3","size":"3929"},{"price":"0.31","size":"9591.93"},{"price":"0.32","size":"13138"},{"price":"0.33","size":"30881"},{"price":"0.34","size":"27615.9"},{"price":"0.35","size":"29150.49"},{"price":"0.36","size":"84806.13"},{"price":"0.37","size":"290.72"}],"asks":[{"price":"0.99","size":"33.04"},{"price":"0.98","size":"2000"},{"price":"0.97","size":"44.99"},{"price":"0.95","size":"118"},{"price":"0.94","size":"110"},{"price":"0.93","size":"8.57"},{"price":"0.87","size":"50"},{"price":"0.67","size":"1000"},{"price":"0.65","size":"1400"},{"price":"0.64","size":"2145"},{"price":"0.52","size":"500"},{"price":"0.51","size":"125"},{"price":"0.5","size":"300"},{"price":"0.49","size":"7"},{"price":"0.47","size":"5555"},{"price":"0.46","size":"3222"},{"price":"0.45","size":"20927"},{"price":"0.44","size":"4322"},{"price":"0.43","size":"3137"},{"price":"0.42","size":"533"},{"price":"0.41","size":"2045"},{"price":"0.4","size":"2732.32"},{"price":"0.39","size":"5245.12"},{"price":"0.38","size":"35150.79"}],"hash":"2940c6d9560658d95dfb1c58a6f7120563058b79","timestamp":"1788786377421","event_type":"book"}
{"market":"0xd23bf61367002265932ce5ae32052aac970c889da8518a2487b5e8a5f1e0693b","asset_id":"114602688616062054693464639818826590702731982636255124778328943187816056373369","price":"0.63","size":"7.555554","fee_rate_bps":"0","side":"BUY","timestamp":"1788786377492","event_type":"last_trade_price","transaction_hash":"0x4d811fbb90581905c83f7d471c8904721fb097b303bac1becec09907b0d860ba"}
{"market":"0xd23bf61367002265932ce5ae32052aac970c889da8518a2487b5e8a5f1e0693b","price_changes":[{"asset_id":"114602688616062054693464639818826590702731982636255124778328943187816056373369","price":"0.6","size":"2782.32","side":"BUY","hash":"7f4a52b5b2ac123a037618018d79b80ae10465ff","best_bid":"0.62","best_ask":"0.63"},{"asset_id":"112222077780534073126353733665449794547376835979729917699348268168151417239731","price":"0.4","size":"2782.32","side":"SELL","hash":"9ff49c97b654acd3f89a761c3ff05c2cf949036f","best_bid":"0.37","best_ask":"0.38"}],"timestamp":"1788786390426","event_type":"price_change"}
{"market":"0xd23bf61367002265932ce5ae32052aac970c889da8518a2487b5e8a5f1e0693b","price_changes":[{"asset_id":"112222077780534073126353733665449794547376835979729917699348268168151417239731","price":"0.35","size":"29200.49","side":"BUY","hash":"539af6df2f19805b8375b77794a2f1c592356459","best_bid":"0.37","best_ask":"0.38"},{"asset_id":"114602688616062054693464639818826590702731982636255124778328943187816056373369","price":"0.65","size":"29200.49","side":"SELL","hash":"dca8c1d5d4f53a372dc43dbac94ca0ca9056afc6","best_bid":"0.62","best_ask":"0.63"}],"timestamp":"1788786390428","event_type":"price_change"}
{"market":"0xd23bf61367002265932ce5ae32052aac970c889da8518a2487b5e8a5f1e0693b","price_changes":[{"asset_id":"114602688616062054693464639818826590702731982636255124778328943187816056373369","price":"0.62","size":"35155.79","side":"BUY","hash":"91a2efa3ce5dc443de009e64e24bf9cc45e2b72b","best_bid":"0.62","best_ask":"0.63"},{"asset_id":"112222077780534073126353733665449794547376835979729917699348268168151417239731","price":"0.38","size":"35155.79","side":"SELL","hash":"c13c78343b48870034975b21948c7e8738182fff","best_bid":"0.37","best_ask":"0.38"}],"timestamp":"1788786395206","event_type":"price_change"}
{"market":"0xd23bf61367002265932ce5ae32052aac970c889da8518a2487b5e8a5f1e0693b","price_changes":[{"asset_id":"112222077780534073126353733665449794547376835979729917699348268168151417239731","price":"0.36","size":"84811.13","side":"BUY","hash":"aa6a7cebd8c79a3178bb5a195fe1f57b97f9d0be","best_bid":"0.37","best_ask":"0.38"},{"asset_id":"114602688616062054693464639818826590702731982636255124778328943187816056373369","price":"0.64","size":"84811.13","side":"SELL","hash":"448307ceb566f786038002c928802adfea479534","best_bid":"0.62","best_ask":"0.63"}],"timestamp":"1788786395500","event_type":"price_change"}
{"market":"0xd23bf61367002265932ce5ae32052aac970c889da8518a2487b5e8a5f1e0693b","price_changes":[{"asset_id":"114602688616062054693464639818826590702731982636255124778328943187816056373369","price":"0.67","size":"29453","side":"SELL","hash":"8ebd2787fcbe8179c0f109eedc0454c1acff9b63","best_bid":"0.62","best_ask":"0.63"},{"asset_id":"112222077780534073126353733665449794547376835979729917699348268168151417239731","price":"0.33","size":"29453","side":"BUY","hash":"9980376689488d3f25abe2e29e397a56e3820cf9","best_bid":"0.37","best_ask":"0.38"}],"timestamp":"1788786398541","event_type":"price_change"}
{"market":"0xd23bf61367002265932ce5ae32052aac970c889da8518a2487b5e8a5f1e0693b","price_changes":[{"asset_id":"114602688616062054693464639818826590702731982636255124778328943187816056373369","price":"0.62","size":"35160.79","side":"BUY","hash":"c1986d6be7ca92769d99ca934a46dc00a88e66e1","best_bid":"0.62","best_ask":"0.63"},{"asset_id":"112222077780534073126353733665449794547376835979729917699348268168151417239731","price":"0.38","size":"35160.79","side":"SELL","hash":"b12ec100bb41f6b96d205a873001ab7e1b8ff0fe","best_bid":"0.37","best_ask":"0.38"}],"timestamp":"1788786399904","event_type":"price_change"}
{"market":"0xd23bf61367002265932ce5ae32052aac970c889da8518a2487b5e8a5f1e0693b","price_changes":[{"asset_id":"112222077780534073126353733665449794547376835979729917699348268168151417239731","price":"0.32","size":"12138","side":"BUY","hash":"3fd2b713efc8b124c11bf0af0182be627f200cc0","best_bid":"0.37","best_ask":"0.38"},{"asset_id":"114602688616062054693464639818826590702731982636255124778328943187816056373369","price":"0.68","size":"12138","side":"SELL","hash":"d0d507e7afbc5c9615bc83bbd0a1b0d2215ca518","best_bid":"0.62","best_ask":"0.63"}],"timestamp":"1788786423195","event_type":"price_change"}
{"market":"0xd23bf61367002265932ce5ae32052aac970c889da8518a2487b5e8a5f1e0693b","price_changes":[{"asset_id":"114602688616062054693464639818826590702731982636255124778328943187816056373369","price":"0.67","size":"30881","side":"SELL","hash":"390d1d1f3b280982e5e25e6701c5ce7f61dc4839","best_bid":"0.62","best_ask":"0.63"},{"asset_id":"112222077780534073126353733665449794547376835979729917699348268168151417239731","price":"0.33","size":"30881","side":"BUY","hash":"ef3c7672f6398ffedfd5540ce558570029f41fa0","best_bid":"0.37","best_ask":"0.38"}],"timestamp":"1788786443547","event_type":"price_change"}
